Error：错误的基类，其他错误都继承自该类型
EvalError：Eval 函数执行异常
RangeError：数组越界
ReferenceError：尝试引用一个未被定义的变量时，将会抛出此异常
SyntaxError：语法解析不合理
TypeError：类型错误，用来表示值的类型非预期类型时发生的错误
URIError：以一种错误的方式使用全局 URI 处理函数而产生的错误

```js

try {
  // 可能会导致错误的代码
} catch (error) {
  // 在错误发生时怎么处理
}

// 无法捕获异步错误
```

```js
/**
 * @param {String}  message    错误信息
 * @param {String}  source     出错文件
 * @param {Number}  lineno     行号
 * @param {Number}  colno      列号
 * @param {Object}  error      Error对象（对象）
 */
window.onerror = function (message, source, lineno, colno, error) {
  console.log("捕获到异常：", { message, source, lineno, colno, error });
};
// 同步错误可以捕获到，但是，请注意 window.error 无法捕获静态资源异常和 JS 代码错误。
```

Promise 异常
```js
window.addEventListener("unhandledrejection", function (e) {
  e.preventDefault();
  console.log("捕获到 promise 错误了");
  console.log("错误的原因是", e.reason);
  console.log("Promise 对象是", e.promise);
  return true;
});

Promise.reject("promise error");
new Promise((resolve, reject) => {
  reject("promise error");
});
new Promise((resolve) => {
  resolve();
}).then(() => {
  throw "promise error";
});

```
